Workbook

Sheet Investitionen, Anl. 1
B1: Anlage 1
A2: Investitionen (Angaben in Euro, ohne Mwst.)
A4: Grundstücke
A6: Art | B6: Wert
A8: Summe 1 | B8: =SUM(B7) -> 0
A10: Gebäude / Bauliche Investitionen
A11: Anschaffungsgenstand | B11: Anschaffungswert
A12: Art | B12: Wert
A13: diverse Installationen / Umbauten
A14: Elektroarbeiten
A15: Renovierung
A17: Summe 2 | B17: =SUM(B13:B16) -> 0
A19: Betriebs- und Geschäftsausstattungen
A20: Anschaffungsgenstand | B20: Anschaffungswert
A21: Laptops, Monitor, Büroausstattung | B21: 1500
A22: Branding/Logo, Domain, Website | B22: 800
A23: Visitenkarten
A26: Summe 3 | B26: =SUM(B21:B25) -> 2300
A28: Geringwertige Wirtschaftsgüter (unter 800,00 €)
A29: Anschaffungsgegenstand | B29: Anschaffungswert
A30: Testgeräte, kleines Zubehör | B30: 500
A35: Summe 4 | B35: =SUM(B30:B34) -> 500
A37: Geringwertige Wirtschaftsgüter (801,00 € - 1.000,00 €)
A38: Anschaffungsgegenstand | B38: Anschaffungswert
A39: Homepage
A40: Tablet / zusätzliches Gerät | B40: 700
A48: Summe 5 | B48: =SUM(B39:B47) -> 700
G49: i | H49: 3500
A50: Maschinen / maschinelle Anlagen (über 1.000,00 €) | G50: Gesamt Aufwand und Ausgaben | H50: 23420
A51: Anschaffungsgegenstand | B51: Anschaffungswert
A57: Summe 6 | B57: =SUM(B52:B56) -> 0
A59: Investitionen gesamt / Summe 1 bis 6 | B59: =B57+B48+B35+B26+B17+B8 -> 3500

Sheet betr. Aufw, Anl.2, monatl.
M1: Anlage 2
A2: Kostenplanung (Angaben in Euro, ohne Mwst., monatlich)
A4: 1. Sonstiger betrieblicher Aufwand
G5: 1. Jahr
A6: Zeitraum | B6: 1 | C6: 2 | D6: 3 | E6: 4 | F6: 5 | G6: 6 | H6: 7 | I6: 8 | J6: 9 | K6: 10 | L6: 11 | M6: 12
A7: Büro/Co-Working | B7: 250 | C7: 250 | D7: 250 | E7: 250 | F7: 250 | G7: 250 | H7: 250 | I7: 250 | J7: 250 | K7: 250 | L7: 250 | M7: 250
A8: Strom, Gas
A9: Reinigung
A10: Büromaterial | B10: 30 | C10: 30 | D10: 30 | E10: 30 | F10: 30 | G10: 30 | H10: 30 | I10: 30 | J10: 30 | K10: 30 | L10: 30 | M10: 30
A11: Telefon/Fax/Internet | B11: 60 | C11: 60 | D11: 60 | E11: 60 | F11: 60 | G11: 60 | H11: 60 | I11: 60 | J11: 60 | K11: 60 | L11: 60 | M11: 60
A12: Porto
A13: Server/Cloud/Hosting | B13: 250 | C13: 250 | D13: 250 | E13: 250 | F13: 250 | G13: 250 | H13: 250 | I13: 250 | J13: 250 | K13: 250 | L13: 250 | M13: 250
A14: Marketing/Werbung | B14: 300 | C14: 300 | D14: 300 | E14: 300 | F14: 300 | G14: 300 | H14: 300 | I14: 300 | J14: 300 | K14: 300 | L14: 300 | M14: 300
A15: Beiträge/Gebühren
A16: Betriebliche Versicherungen | B16: 50 | C16: 50 | D16: 50 | E16: 50 | F16: 50 | G16: 50 | H16: 50 | I16: 50 | J16: 50 | K16: 50 | L16: 50 | M16: 50
A17: Buchhaltung/Steuerberatung | B17: 150 | C17: 150 | D17: 150 | E17: 150 | F17: 150 | G17: 150 | H17: 150 | I17: 150 | J17: 150 | K17: 150 | L17: 150 | M17: 150
A18: anteilige gewerbl. KfZ-Kosten + Steuer etc.
A19: Fachliteratur
A20: Reisekosten
A21: Werterhaltung für Einrichtungen
A22: Fahrzeugsteuer
A23: Software-Tools/Lizenzen | B23: 150 | C23: 150 | D23: 150 | E23: 150 | F23: 150 | G23: 150 | H23: 150 | I23: 150 | J23: 150 | K23: 150 | L23: 150 | M23: 150
A24: Leasingrate
A25: Kontoführung | B25: 20 | C25: 20 | D25: 20 | E25: 20 | F25: 20 | G25: 20 | H25: 20 | I25: 20 | J25: 20 | K25: 20 | L25: 20 | M25: 20
A26: Weiterbildung/Fachliteratur | B26: 50 | C26: 50 | D26: 50 | E26: 50 | F26: 50 | G26: 50 | H26: 50 | I26: 50 | J26: 50 | K26: 50 | L26: 50 | M26: 50
A27: Sonst. betriebl. Aufwand | B27: 100 | C27: 100 | D27: 100 | E27: 100 | F27: 100 | G27: 100 | H27: 100 | I27: 100 | J27: 100 | K27: 100 | L27: 100 | M27: 100
A28: Sonst. betriebl. Aufwand | B28: =SUM(B7:B27) -> 1410 | C28: =SUM(C7:C27) -> 1410 | D28: =SUM(D7:D27) -> 1410 | E28: =SUM(E7:E27) -> 1410 | F28: =SUM(F7:F27) -> 1410 | G28: =SUM(G7:G27) -> 1410 | H28: =SUM(H7:H27) -> 1410 | I28: =SUM(I7:I27) -> 1410 | ... M28: =SUM(M7:M27) -> 1410
A30: 2. Sonstige betriebliche Ausgaben
A31: Gründungskosten (Rechtsform, Anmeldung, Recht/Datenschutz) | B31: 1500
A32: Mietkaution (Co-Working) | B32: 300
A33: Software-Plattform + Marketing/Launch + Liquiditätsreserve | B33: 4700
A34: Sonst. betriebl. Ausgaben | B34: =SUM(B31:B33) -> 6500 | C34: =SUM(C31:C33) -> 0 | D34: =SUM(D31:D33) -> 0 | E34: =SUM(E31:E33) -> 0 | F34: =SUM(F31:F33) -> 0 | G34: =SUM(G31:G33) -> 0 | H34: =SUM(H31:H33) -> 0 | I34: =SUM(I31:I33) -> 0 | ... M34: =SUM(M31:M33) -> 0
A35: Gesamt Aufwand und Ausgaben | B35: =SUM(B34,B28) -> 7910 | C35: =SUM(C34,C28) -> 1410 | D35: =SUM(D34,D28) -> 1410 | E35: =SUM(E34,E28) -> 1410 | F35: =SUM(F34,F28) -> 1410 | G35: =SUM(G34,G28) -> 1410 | H35: =SUM(H34,H28) -> 1410 | I35: =SUM(I34,I28) -> 1410 | ... M35: =SUM(M34,M28) -> 1410 | N35: =SUM(B35:M35) -> 23420 | O35: expense | P35: 3500

Sheet betr. Aufw, Anl.2,quart
A2: Kostenplanung (Angaben in Euro, ohne Mwst.)
A4: 1. Sonstiger betrieblicher Aufwand
B5: 2. Jahr | F5: 3. Jahr
A6: Zeitraum | B6: I. Q. | C6: II. Q. | D6: III. Q. | E6: IV. Q. | F6: I. Q. | G6: II. Q. | H6: III. Q. | I6: IV. Q.
A7: Büro/Co-Working | B7: 750 | C7: 750 | D7: 750 | E7: 750 | F7: 750 | G7: 750 | H7: 750 | I7: 750
A8: Strom, Gas
A9: Reinigung
A10: Büromaterial | B10: 90 | C10: 90 | D10: 90 | E10: 90 | F10: 90 | G10: 90 | H10: 90 | I10: 90
A11: Telefon/Fax/Internet | B11: 180 | C11: 180 | D11: 180 | E11: 180 | F11: 180 | G11: 180 | H11: 180 | I11: 180
A12: Porto
A13: Server/Cloud/Hosting | B13: 750 | C13: 750 | D13: 750 | E13: 750 | F13: 750 | G13: 750 | H13: 750 | I13: 750
A14: Marketing/Werbung | B14: 900 | C14: 900 | D14: 900 | E14: 900 | F14: 900 | G14: 900 | H14: 900 | I14: 900
A15: Kontoführung | B15: 60 | C15: 60 | D15: 60 | E15: 60 | F15: 60 | G15: 60 | H15: 60 | I15: 60
A16: Betriebliche Versicherungen | B16: 150 | C16: 150 | D16: 150 | E16: 150 | F16: 150 | G16: 150 | H16: 150 | I16: 150
A17: Buchhaltung/Steuerberatung | B17: 450 | C17: 450 | D17: 450 | E17: 450 | F17: 450 | G17: 450 | H17: 450 | I17: 450
A18: anteilige gewerbl. KfZ-Kosten
A19: Weiterbildung/Fachliteratur | B19: 150 | C19: 150 | D19: 150 | E19: 150 | F19: 150 | G19: 150 | H19: 150 | I19: 150
A20: Reisekosten
A21: Werterhaltung für Einrichtungen
A22: Fahrzeugsteuer
A23: Software-Tools/Lizenzen | B23: 450 | C23: 450 | D23: 450 | E23: 450 | F23: 450 | G23: 450 | H23: 450 | I23: 450
A24: Sonst. betriebl. Aufwand | B24: 300 | C24: 300 | D24: 300 | E24: 300 | F24: 300 | G24: 300 | H24: 300 | I24: 300
A25: Sonst. betriebl. Aufwand | B25: =SUM(B7:B24) -> 4230 | C25: =SUM(C7:C24) -> 4230 | D25: =SUM(D7:D24) -> 4230 | E25: =SUM(E7:E24) -> 4230 | F25: =SUM(F7:F24) -> 4230 | G25: =SUM(G7:G24) -> 4230 | H25: =SUM(H7:H24) -> 4230 | I25: =SUM(I7:I24) -> 4230
A27: 2. Sonstige betriebliche Ausgaben
A30: Sonst. betriebl. Ausgaben | B30: =SUM(B28:B29) -> 0 | C30: =SUM(C28:C29) -> 0 | D30: =SUM(D28:D29) -> 0 | E30: =SUM(E28:E29) -> 0 | F30: =SUM(F28:F29) -> 0 | G30: =SUM(G28:G29) -> 0 | H30: =SUM(H28:H29) -> 0 | I30: =SUM(I28:I29) -> 0
A31: Gesamt Aufwand und Ausgaben | B31: =SUM(B30,B25) -> 4230 | C31: =SUM(C30,C25) -> 4230 | D31: =SUM(D30,D25) -> 4230 | E31: =SUM(E30,E25) -> 4230 | F31: =SUM(F30,F25) -> 4230 | G31: =SUM(G30,G25) -> 4230 | H31: =SUM(H30,H25) -> 4230 | I31: =SUM(I30,I25) -> 4230

Sheet priv. Aufwendungen, Anl. 3
C1: Anlage 3
A3: Ermittlung des Unternehmerlohns (Angaben in Euro)
B5: Ausgaben | C5: Ausgaben
B6: Monat | C6: Quartal
A7: Lebenshaltung | B7: Euro | C7: Euro
A8: Verpflegung | B8: 350 | C8: =B8*3 -> 1050
A9: Kleidung | B9: 100 | C9: =B9*3 -> 300
A10: Telefon/Fax/Internet/Kabel | B10: 60 | C10: =B10*3 -> 180
A11: Private Kfz-Nutzung | B11: 250 | C11: =B11*3 -> 750
A12: Sonstige (Friseur, Kosmetik, Kita, GEZ) | B12: 150 | C12: =B12*3 -> 450
C13: =B13*3 -> 0
A14: Summe: | B14: =SUM(B8:B13) -> 910 | C14: =B14*3 -> 2730
A15: Miete / Wohnkosten | B15: Euro | C15: Euro
A16: Warmmiete | B16: 800 | C16: =B16*3 -> 2400
A17: Heizung | B17: 0 | C17: =B17*3 -> 0
A18: Betriebskosten u./o. WW-Vorauszahlung | B18: 0 | C18: =B18*3 -> 0
A19: Strom/Gas | B19: 100 | C19: =B19*3 -> 300
C20: =B20*3 -> 0
C21: =B21*3 -> 0
C22: =B22*3 -> 0
A23: Summe: | B23: =SUM(B16:B22) -> 900 | C23: =B23*3 -> 2700
A24: Krankenversicherung (KV) | B24: Euro | C24: Euro
A25: Gesetzliche KV freiwillig | B25: 450 | C25: =B25*3 -> 1350
A26: Zusatzversicherung (privat) | B26: 0 | C26: =B26*3 -> 0
A27: Private KV (ambulant/stationär/Zahnarzt, etc.) | B27: 0 | C27: =B27*3 -> 0
A28: Krankenhaustagegeld/Krankentagegeld (Pflegeversicherung) | B28: 0 | C28: =B28*3 -> 0
A29: Summe: | B29: =SUM(B25:B28) -> 450 | C29: =B29*3 -> 1350
A30: Altersversorgung | B30: Euro | C30: Euro
A31: Beiträge zur freiwilligen/gesetzlichen Rentenversicherung | B31: 200 | C31: =B31*3 -> 600
A32: Beiträge zur privaten Rentenversicherung | B32: 0 | C32: =B32*3 -> 0
A33: Summe: | B33: =SUM(B31:B32) -> 200 | C33: =B33*3 -> 600
A34: Versicherungen | B34: Euro | C34: Euro
A35: Lebensversicherung | B35: 0 | C35: =B35*3 -> 0
A36: Rechtsschutzversicherung | B36: 30 | C36: =B36*3 -> 90
A37: Hausratversicherung | B37: 15 | C37: =B37*3 -> 45
A38: Haftpflichtversicherung | B38: 10 | C38: =B38*3 -> 30
C39: =B39*3 -> 0
C40: =B40*3 -> 0
A41: Summe: | B41: =SUM(B35:B40) -> 55 | C41: =B41*3 -> 165
A42: Sonstige vertragliche Verpflichtungen | B42: Euro | C42: Euro
...

Sheet Aufw.- Ertr-pl., Anl. 4, monatl
M1: Anlage 4
A2: Aufwands- und Ertragsplanung (Angaben in Euro, ohne Mwst., monatlich)
A3: Legende: Geschäftsfeld 1: | B3: Software-Plattform (Hauptumsatzquelle)
A4: Geschäftsfeld 2:
A5: Geschäftsfeld 3:
G7: 1. Jahr
A8: Zeitraum | B8: 1 | C8: 2 | D8: 3 | E8: 4 | F8: 5 | G8: 6 | H8: 7 | I8: 8 | J8: 9 | K8: 10 | L8: 11 | M8: 12
A9: Umsatzerlöse (ohne USt) GF 1 | B9: 8000 | C9: 9000 | D9: 10000 | E9: 11000 | F9: 12000 | G9: 12500 | H9: 13000 | I9: 13500 | J9: 14000 | K9: 14500 | L9: 15000 | M9: 22010
A10: ./. Materialverbrauch./Warenentnahme GF 1 | B10: 0 | C10: 0 | D10: 0 | E10: 0 | F10: 0 | G10: 0 | H10: 0 | I10: 0 | J10: 0 | K10: 0 | L10: 0 | M10: 0
A11: ./. Fremdleistungen (Transp.,Hon. etc.) GF 1 | B11: 0 | C11: 0 | D11: 0 | E11: 0 | F11: 0 | G11: 0 | H11: 0 | I11: 0 | J11: 0 | K11: 0 | L11: 0 | M11: 0
A12: Umsatzerlöse (ohne USt) GF 2 | B12: 0 | C12: 0 | D12: 0 | E12: 0 | F12: 0 | G12: 0 | H12: 0 | I12: 0 | J12: 0 | K12: 0 | L12: 0 | M12: 0
A13: ./. Materialverbrauch./Warenentnahme GF 2 | B13: 0 | C13: 0 | D13: 0 | E13: 0 | F13: 0 | G13: 0 | H13: 0 | I13: 0 | J13: 0 | K13: 0 | L13: 0 | M13: 0
A14: ./. Fremdleistungen (Transp.,Hon. etc.) GF 2 | B14: 0 | C14: 0 | D14: 0 | E14: 0 | F14: 0 | G14: 0 | H14: 0 | I14: 0 | J14: 0 | K14: 0 | L14: 0 | M14: 0
A15: Umsatzerlöse (ohne USt) GF 3 | B15: 0 | C15: 0 | D15: 0 | E15: 0 | F15: 0 | G15: 0 | H15: 0 | I15: 0 | J15: 0 | K15: 0 | L15: 0 | M15: 0
A16: ./. Materialverbrauch./Warenentnahme GF 3 | B16: 0 | C16: 0 | D16: 0 | E16: 0 | F16: 0 | G16: 0 | H16: 0 | I16: 0 | J16: 0 | K16: 0 | L16: 0 | M16: 0
A17: ./. Fremdleistungen (Transp.,Hon. etc.) GF 3 | B17: 0 | C17: 0 | D17: 0 | E17: 0 | F17: 0 | G17: 0 | H17: 0 | I17: 0 | J17: 0 | K17: 0 | L17: 0 | M17: 0
A18: Umsatzerlöse gesamt GF 1, GF 2, GF 3 | B18: =(B9+B12+B15) -> 8000 | C18: =(C9+C12+C15) -> 9000 | D18: =(D9+D12+D15) -> 10000 | E18: =(E9+E12+E15) -> 11000 | F18: =(F9+F12+F15) -> 12000 | G18: =(G9+G12+G15) -> 12500 | H18: =(H9+H12+H15) -> 13000 | I18: =(I9+I12+I15) -> 13500 | ... M18: =(M9+M12+M15) -> 22010
A19: Rohertrag | B19: =B18-(B10+B11+B13+B14+B16+B17) -> 8000 | C19: =C18-(C10+C11+C13+C14+C16+C17) -> 9000 | D19: =D18-(D10+D11+D13+D14+D16+D17) -> 10000 | E19: =E18-(E10+E11+E13+E14+E16+E17) -> 11000 | F19: =F18-(F10+F11+F13+F14+F16+F17) -> 12000 | G19: =G18-(G10+G11+G13+G14+G16+G17) -> 12500 | H19: =H18-(H10+H11+H13+H14+H16+H17) -> 13000 | I19: =I18-(I10+I11+I13+I14+I16+I17) -> 13500 | ... M19: =M18-(M10+M11+M13+M14+M16+M17) -> 22010
A20: ./. sonst. betriebl. Aufwand (Anlage 2) | B20: ='betr. Aufw, Anl.2, monatl.'!B28 -> 1410 | C20: ='betr. Aufw, Anl.2, monatl.'!C28 -> 1410 | D20: ='betr. Aufw, Anl.2, monatl.'!D28 -> 1410 | E20: ='betr. Aufw, Anl.2, monatl.'!E28 -> 1410 | F20: ='betr. Aufw, Anl.2, monatl.'!F28 -> 1410 | G20: ='betr. Aufw, Anl.2, monatl.'!G28 -> 1410 | H20: ='betr. Aufw, Anl.2, monatl.'!H28 -> 1410 | I20: ='betr. Aufw, Anl.2, monatl.'!I28 -> 1410 | ... M20: ='betr. Aufw, Anl.2, monatl.'!M28 -> 1410
A21: ./. Personalaufw./soz. Abg. (o. Unternehmerlohn) | B21: 0 | C21: 0 | D21: 0 | E21: 0 | F21: 0 | G21: 0 | H21: 0 | I21: 0 | J21: 0 | K21: 0 | L21: 0 | M21: 0
A22: ./. Abschreibungen | B22: 0 | C22: 0 | D22: 0 | E22: 0 | F22: 0 | G22: 0 | H22: 0 | I22: 0 | J22: 0 | K22: 0 | L22: 0 | M22: 0
A23: + betr. Einnahmen (LKZ) | B23: 0 | C23: 0 | D23: 0 | E23: 0 | F23: 0 | G23: 0 | H23: 0 | I23: 0 | J23: 0 | K23: 0 | L23: 0 | M23: 0
A24: Betriebsergebnis 1 | B24: =B19-SUM(B20:B22)+B23 -> 6590 | C24: =C19-SUM(C20:C22)+C23 -> 7590 | D24: =D19-SUM(D20:D22)+D23 -> 8590 | E24: =E19-SUM(E20:E22)+E23 -> 9590 | F24: =F19-SUM(F20:F22)+F23 -> 10590 | G24: =G19-SUM(G20:G22)+G23 -> 11090 | H24: =H19-SUM(H20:H22)+H23 -> 11590 | I24: =I19-SUM(I20:I22)+I23 -> 12090 | ... M24: =M19-SUM(M20:M22)+M23 -> 20600
A25: + Gründungszuschuss/Einstiegsgeld | B25: 0 | C25: 0 | D25: 0 | E25: 0 | F25: 0 | G25: 0 | H25: 0 | I25: 0 | J25: 0 | K25: 0 | L25: 0 | M25: 0
A26: ./. Unternehmerlohn (Anl. 3) | B26: =('priv. Aufwendungen, Anl. 3'!B54) -> 2765 | C26: =('priv. Aufwendungen, Anl. 3'!B54) -> 2765 | D26: =('priv. Aufwendungen, Anl. 3'!B54) -> 2765 | E26: =('priv. Aufwendungen, Anl. 3'!B54) -> 2765 | F26: =('priv. Aufwendungen, Anl. 3'!B54) -> 2765 | G26: =('priv. Aufwendungen, Anl. 3'!B54) -> 2765 | H26: =('priv. Aufwendungen, Anl. 3'!B54) -> 2765 | I26: =('priv. Aufwendungen, Anl. 3'!B54) -> 2765 | J26: =('priv. Aufwendungen, Anl. 3'!B54) -> 2765 | K26: =('priv. Aufwendungen, Anl. 3'!B54) -> 2765 | L26: =('priv. Aufwendungen, Anl. 3'!B54) -> 2765 | M26: =('priv. Aufwendungen, Anl. 3'!B54) -> 2765
A27: ausgewiesenes Ergebnis (zur Info) | B27: =B24+B25-B26 -> 3825 | C27: =C24+C25-C26 -> 4825 | D27: =D24+D25-D26 -> 5825 | E27: =E24+E25-E26 -> 6825 | F27: =F24+F25-F26 -> 7825 | G27: =G24+G25-G26 -> 8325 | H27: =H24+H25-H26 -> 8825 | I27: =I24+I25-I26 -> 9325 | ... M27: =M24+M25-M26 -> 17835 | N27: =sum(B27:M27) -> 104410
A29: Planungsziel | B29: Planungsziel: Jahr 1: 154.500 € Nettoumsatz / ca. 137.580 € Gewinn vor Steuern / ca. 100.000 € Gewinn nach Steuer (Planannahme 27,32 %)

Sheet Aufw.- Ertr-pl., Anl. 4, quart
A2: Aufwands- und Ertragsplanung (Angaben in Euro, ohne Mwst.)
A3: Legende: Geschäftsfeld 1: | B3: Software-Plattform (Hauptumsatzquelle)
A4: Geschäftsfeld 2:
A5: Geschäftsfeld 3:
C7: 2. Jahr | G7: 3. Jahr
A8: Zeitraum | B8: I. Q. | C8: II. Q. | D8: III. Q. | E8: IV. Q. | F8: I. Q. | G8: II. Q. | H8: III. Q. | I8: IV. Q.
A9: Umsatzerlöse (ohne USt) GF 1 | B9: 45000 | C9: 48000 | D9: 52000 | E9: 55000 | F9: 58000 | G9: 62000 | H9: 64000 | I9: 66000
A10: ./. Materialverbrauch./Warenentnahme GF 1 | B10: 0 | C10: 0 | D10: 0 | E10: 0 | F10: 0 | G10: 0 | H10: 0 | I10: 0
A11: ./. Fremdleistungen (Transp.,Hon. etc.) GF 1 | B11: 0 | C11: 0 | D11: 0 | E11: 0 | F11: 0 | G11: 0 | H11: 0 | I11: 0
A12: Umsatzerlöse (ohne USt) GF 2 | B12: 0 | C12: 0 | D12: 0 | E12: 0 | F12: 0 | G12: 0 | H12: 0 | I12: 0
A13: ./. Materialverbrauch./Warenentnahme GF 2 | B13: 0 | C13: 0 | D13: 0 | E13: 0 | F13: 0 | G13: 0 | H13: 0 | I13: 0
A14: ./. Fremdleistungen (Transp.,Hon. etc.) GF 2 | B14: 0 | C14: 0 | D14: 0 | E14: 0 | F14: 0 | G14: 0 | H14: 0 | I14: 0
A15: Umsatzerlöse (ohne USt) GF 3 | B15: 0 | C15: 0 | D15: 0 | E15: 0 | F15: 0 | G15: 0 | H15: 0 | I15: 0
A16: ./. Materialverbrauch./Warenentnahme GF 3 | B16: 0 | C16: 0 | D16: 0 | E16: 0 | F16: 0 | G16: 0 | H16: 0 | I16: 0
A17: ./. Fremdleistungen (Transp.,Hon. etc.) GF 3 | B17: 0 | C17: 0 | D17: 0 | E17: 0 | F17: 0 | G17: 0 | H17: 0 | I17: 0
A18: Umsatzerlöse gesamt GF 1, GF 2, GF 3 | B18: =(B9+B12+B15) -> 45000 | C18: =(C9+C12+C15) -> 48000 | D18: =(D9+D12+D15) -> 52000 | E18: =(E9+E12+E15) -> 55000 | F18: =(F9+F12+F15) -> 58000 | G18: =(G9+G12+G15) -> 62000 | H18: =(H9+H12+H15) -> 64000 | I18: =(I9+I12+I15) -> 66000
A19: Rohertrag | B19: =B18-(B10+B11+B13+B14+B16+B17) -> 45000 | C19: =C18-(C10+C11+C13+C14+C16+C17) -> 48000 | D19: =D18-(D10+D11+D13+D14+D16+D17) -> 52000 | E19: =E18-(E10+E11+E13+E14+E16+E17) -> 55000 | F19: =F18-(F10+F11+F13+F14+F16+F17) -> 58000 | G19: =G18-(G10+G11+G13+G14+G16+G17) -> 62000 | H19: =H18-(H10+H11+H13+H14+H16+H17) -> 64000 | I19: =I18-(I10+I11+I13+I14+I16+I17) -> 66000
A20: ./. sonst. betriebl. Aufwand (Anlage 2) | B20: ='betr. Aufw, Anl.2,quart'!B25 -> 4230 | C20: ='betr. Aufw, Anl.2,quart'!C25 -> 4230 | D20: ='betr. Aufw, Anl.2,quart'!D25 -> 4230 | E20: ='betr. Aufw, Anl.2,quart'!E25 -> 4230 | F20: ='betr. Aufw, Anl.2,quart'!F25 -> 4230 | G20: ='betr. Aufw, Anl.2,quart'!G25 -> 4230 | H20: ='betr. Aufw, Anl.2,quart'!H25 -> 4230 | I20: ='betr. Aufw, Anl.2,quart'!I25 -> 4230
A21: ./. Personalaufw./soz. Abg. (o. Unternehmerlohn) | B21: 0 | C21: 0 | D21: 0 | E21: 0 | F21: 0 | G21: 0 | H21: 0 | I21: 0
A22: ./. Abschreibungen | B22: 0 | C22: 0 | D22: 0 | E22: 0 | F22: 0 | G22: 0 | H22: 0 | I22: 0
A23: + betr. Einnahmen (LKZ) | B23: 0 | C23: 0 | D23: 0 | E23: 0 | F23: 0 | G23: 0 | H23: 0 | I23: 0
A24: Betriebsergebnis 1 | B24: =B19-SUM(B20:B22)+B23 -> 40770 | C24: =C19-SUM(C20:C22)+C23 -> 43770 | D24: =D19-SUM(D20:D22)+D23 -> 47770 | E24: =E19-SUM(E20:E22)+E23 -> 50770 | F24: =F19-SUM(F20:F22)+F23 -> 53770 | G24: =G19-SUM(G20:G22)+G23 -> 57770 | H24: =H19-SUM(H20:H22)+H23 -> 59770 | I24: =I19-SUM(I20:I22)+I23 -> 61770
A25: + Überbrückungsgeld/Einstiegsgeld | B25: 0 | C25: 0 | D25: 0 | E25: 0 | F25: 0 | G25: 0 | H25: 0 | I25: 0
A26: ./. Unternehmerlohn (Anl. 3) | B26: ='priv. Aufwendungen, Anl. 3'!C54 -> 8295 | C26: ='priv. Aufwendungen, Anl. 3'!C54 -> 8295 | D26: ='priv. Aufwendungen, Anl. 3'!C54 -> 8295 | E26: ='priv. Aufwendungen, Anl. 3'!C54 -> 8295 | F26: ='priv. Aufwendungen, Anl. 3'!C54 -> 8295 | G26: ='priv. Aufwendungen, Anl. 3'!C54 -> 8295 | H26: ='priv. Aufwendungen, Anl. 3'!C54 -> 8295 | I26: ='priv. Aufwendungen, Anl. 3'!C54 -> 8295
A27: ausgewiesenes Ergebnis (zur Info) | B27: =B24+B25-B26 -> 32475 | C27: =C24+C25-C26 -> 35475 | D27: =D24+D25-D26 -> 39475 | E27: =E24+E25-E26 -> 42475 | F27: =F24+F25-F26 -> 45475 | G27: =G24+G25-G26 -> 49475 | H27: =H24+H25-H26 -> 51475 | I27: =I24+I25-I26 -> 53475 | J27: =SUM(B27:I27) -> 349800
A29: Umsatzentwicklung | B29: Jahr 2: 84.000 € / Jahr 3: 108.000 € Nettoumsatz

Sheet Finanzbedarf netto, Anl. 5
B1: Anlage 5
A4: Finanzbedarf (Angaben in Euro, ohne Mwst.)
A6: 1. Betriebsmittel in der Gründungsphase (I.Quartal)
A10: Waren-/Materialentnahme | B10: =SUM('Aufw.- Ertr-pl., Anl. 4, monatl'!B10:D10)+SUM('Aufw.- Ertr-pl., Anl. 4, monatl'!B13:D13)+SUM('Aufw.- Ertr-pl., Anl. 4, monatl'!B16:D16) -> 0
A11: Fremdleistungen (Transporte, Honorare etc.) | B11: =SUM('Aufw.- Ertr-pl., Anl. 4, monatl'!B11:G11)+SUM('Aufw.- Ertr-pl., Anl. 4, monatl'!B14:D14)+SUM('Aufw.- Ertr-pl., Anl. 4, monatl'!B14:G17) -> 0
A12: Personalaufwand + soz. Abgaben | B12: =SUM('Aufw.- Ertr-pl., Anl. 4, monatl'!B21:D21) -> 0
A13: Sonstiger betrieblicher Aufwand | B13: =SUM('betr. Aufw, Anl.2, monatl.'!B28:D28) -> 4230
A14: Sonstige betriebliche Ausgaben | B14: ='betr. Aufw, Anl.2, monatl.'!B34:D34 -> 6500
A16: Summe 1. | B16: =SUM(B10:B15) -> 10730
A18: 2. Investitionen
A20: Grundstücke | B20: ='Investitionen, Anl. 1'!B8 -> 0
A21: Gebäude / Bauliche Investitionen | B21: ='Investitionen, Anl. 1'!B17 -> 0
A22: Betriebs- und Geschäftsausstattung | B22: ='Investitionen, Anl. 1'!B26 -> 2300
A23: Geringwertige Wirtschaftsgüter (unter 250,00 €) | B23: ='Investitionen, Anl. 1'!B35 -> 500
A24: Geringwertige Wirtschaftsgüter (251,00 - 1.000,00 €) | B24: ='Investitionen, Anl. 1'!B48 -> 700
A25: Maschinen / maschinelle Anlagen (über 1.000,00 €) | B25: ='Investitionen, Anl. 1'!B57 -> 0
A27: Summe 2. | B27: =SUM(B20:B25) -> 3500
A31: Finanzbedarf/Summe 1. + 2. | B31: =SUM(B16+B27) -> 14230
A35: geplante Finanzierung zur Deckung des
A36: Finanzbedarfs (netto)
A37: Zuschuss JobCenter
A38: Darlehen JobCenter
A39: IBB-Existenzgründerdarlehen
A40: KfW-Startgeld
A41: andere Kreditinstitute (z.B. Hausbankkredit)
A42: andere öffentliche Fördermittel
A43: Eigenkapital
A44: Privatdarlehen
A45: garantierte Zahlungseingänge 1. Quartal
A47: Summe | B47: =SUM(B37:B46) -> 0

Sheet Rentabilitätsvorschau, Anl. 6
D1: Anlage 6
A3: Rentabilitätsvorschau (Angaben in Euro, ohne Mwst.)
B6: 1. Jahr | C6: 2. Jahr | D6: 3. Jahr
A7: Umsatzerlöse | B7: =SUM('Aufw.- Ertr-pl., Anl. 4, monatl'!B18:M18) -> 154510 | C7: =SUM('Aufw.- Ertr-pl., Anl. 4, quart'!B18:E18) -> 200000 | D7: =SUM('Aufw.- Ertr-pl., Anl. 4, quart'!F18:I18) -> 250000
A8: ./. Materialverbrauch/Warenentnahme | B8: =SUM('Aufw.- Ertr-pl., Anl. 4, monatl'!B10:M10)+SUM('Aufw.- Ertr-pl., Anl. 4, monatl'!B13:M13)+SUM('Aufw.- Ertr-pl., Anl. 4, monatl'!B16:M16) -> 0 | C8: =SUM('Aufw.- Ertr-pl., Anl. 4, quart'!B10:E10)+SUM('Aufw.- Ertr-pl., Anl. 4, quart'!B13:E13)+SUM('Aufw.- Ertr-pl., Anl. 4, quart'!B16:E16) -> 0 | D8: =SUM('Aufw.- Ertr-pl., Anl. 4, quart'!F10:I10)+SUM('Aufw.- Ertr-pl., Anl. 4, quart'!F13:I13)+SUM('Aufw.- Ertr-pl., Anl. 4, quart'!F16:I16) -> 0
A9: ./. Fremdleistungen/Transporte | B9: =SUM('Aufw.- Ertr-pl., Anl. 4, monatl'!B11:M11)+SUM('Aufw.- Ertr-pl., Anl. 4, monatl'!B14:M14)+SUM('Aufw.- Ertr-pl., Anl. 4, monatl'!B17:M17) -> 0 | C9: =SUM('Aufw.- Ertr-pl., Anl. 4, quart'!B11:E11)+SUM('Aufw.- Ertr-pl., Anl. 4, quart'!B14:E14)+SUM('Aufw.- Ertr-pl., Anl. 4, quart'!B17:E17) -> 0 | D9: =SUM('Aufw.- Ertr-pl., Anl. 4, quart'!F11:I11)+SUM('Aufw.- Ertr-pl., Anl. 4, quart'!F14:I14)+SUM('Aufw.- Ertr-pl., Anl. 4, quart'!F17:I17) -> 0
A12: betr. Einnahmen (Provisionen etc.) | B12: =SUM('Aufw.- Ertr-pl., Anl. 4, monatl'!B23:M23) -> 0 | C12: =SUM('Aufw.- Ertr-pl., Anl. 4, quart'!B23:E23) -> 0 | D12: =SUM('Aufw.- Ertr-pl., Anl. 4, quart'!F23:I23) -> 0
A13: Rohertrag | B13: =B7-SUM(B8:B11)+B12 -> 154510 | C13: =C7-SUM(C8:C11)+C12 -> 200000 | D13: =D7-SUM(D8:D11)+D12 -> 250000
A14: ./. Aufwendungen
A15: sonst. betriebl. Aufwand (Anlage 2) | B15: =SUM('betr. Aufw, Anl.2, monatl.'!B28:M28) -> 16920 | C15: =SUM('betr. Aufw, Anl.2,quart'!B25:E25) -> 16920 | D15: =SUM('betr. Aufw, Anl.2,quart'!F25:I25) -> 16920
A16: Löhne / Gehälter / gesetzl. soziale Abgaben | B16: =SUM('Aufw.- Ertr-pl., Anl. 4, monatl'!B21:M21) -> 0 | C16: =SUM('Aufw.- Ertr-pl., Anl. 4, quart'!B21:E21) -> 0 | D16: =SUM('Aufw.- Ertr-pl., Anl. 4, quart'!F21:I21) -> 0
A18: Bearbeitungsgebühr 4 % (KfW-Darlehen) | B18: ='Finanzbedarf netto, Anl. 5'!B40*4% -> 0
A19: Ratenzahlung (KfW-Darlehen) | D19: =('Finanzbedarf netto, Anl. 5'!B40/8) -> 0
A20: Zinsen ca. 9% nur bei KfW-Darlehen (ab 1.Jahr) | B20: ='Finanzbedarf netto, Anl. 5'!B40*9% -> 0 | C20: ='Finanzbedarf netto, Anl. 5'!B40*7% -> 0 | D20: ='Finanzbedarf netto, Anl. 5'!C40*9% -> 0
A21: Bearbeitungsgebühr 2 % (IBB-Darlehen) | B21: ='Finanzbedarf netto, Anl. 5'!B39*2% -> 0
A22: Zinsen ca.8,56 % nur (IBB-Darlehen) | B22: ='Finanzbedarf netto, Anl. 5'!B39*8.56% -> 0 | C22: ='Finanzbedarf netto, Anl. 5'!B39*7.87% -> 0 | D22: =('Finanzbedarf netto, Anl. 5'!B39-D23)*(7.87%) -> 0
A23: Ratenzahlung (IBB-Darlehen) | D23: ='Finanzbedarf netto, Anl. 5'!B39/8 -> 0
A24: Bearbeitungsgebühr % (andere Kreditinstitute)
A25: Ratenzahlung (andere Kreditinstitute)
A26: Zinszahlung (andere Kreditinstitute)
A27: Gewinn vor Steuern | B27: =B13+B39-SUM(B15:B26) -> 137590 | C27: =C13+C39-SUM(C15:C26) -> 183080 | D27: =D13+D39-SUM(D15:D26) -> 233080
A28: ./. Abschreibung | B28: =SUM('Aufw.- Ertr-pl., Anl. 4, monatl'!B22:M22) -> 0 | C28: =SUM('Aufw.- Ertr-pl., Anl. 4, quart'!B22:E22) -> 0 | D28: =SUM('Aufw.- Ertr-pl., Anl. 4, quart'!F22:I22) -> 0
A30: Zwischensumme | B30: =B27-SUM(B28:B29) -> 137590 | C30: =C27-SUM(C28:C29) -> 183080 | D30: =D27-SUM(D28:D29) -> 233080
A32: Sonderausgaben
A33: Freibeträge
A34: Aussergewöhnliche Belastungen
A36: zu versteuernde Gewinn (*) | B36: =B30-SUM(B32:B34) -> 137590 | C36: =C30-SUM(C32:C34) -> 183080 | D36: =D30-SUM(D32:D34) -> 233080
A39: nichtrückzahlbare Zuschüsse (z.B. Gründerzuschuss) | B39: =SUM('Aufw.- Ertr-pl., Anl. 4, monatl'!B25:M25) -> 0 | C39: =SUM('Aufw.- Ertr-pl., Anl. 4, quart'!B25:E25) -> 0 | D39: =SUM('Aufw.- Ertr-pl., Anl. 4, quart'!F25:I25) -> 0
A40: Geschätzte Einkommensteuer (Planannahme) | B40: =B36*27.32% -> 37589.588 | C40: =C36*27.32% -> 50017.456 | D40: =D36*27.32% -> 63677.456
A41: Gewinn nach Steuer (Plan) | B41: =B36-B40 -> 100000.41 | C41: =C36-C40 -> 133062.54 | D41: =D36-D40 -> 169402.54
B42: Ledige | D42: Verheiratete
A43: zu versteuerndes Einkommen | B43: Euro | C43: Prozenz | D43: Euro | E43: Prozenz
A44: 5000 | B44: 0 | C44: 0 | D44: =A44*E44 -> 0 | E44: 0
A45: 10000 | B45: =A45*C45 -> 347 | C45: 0.0347 | D45: =A45*E45 -> 0 | E45: 0
A46: 15000 | B46: =A46*C46 -> 1540.5 | C46: 0.1027 | D46: =A46*E46 -> 0 | E46: 0
A47: 20000 | B47: =A47*C47 -> 2910 | C47: 0.1455 | D47: =A47*E47 -> 694 | E47: 0.0347
A48: 25000 | B48: =A48*C48 -> 4397.5 | C48: 0.1759 | D48: =A48*E48 -> 1715 | E48: 0.0686
A49: 30000 | B49: =A49*C49 -> 6009 | C49: 0.2003 | D49: =A49*E49 -> 3081 | E49: 0.1027
A50: 35000 | B50: =A50*C50 -> 7742 | C50: 0.2212 | D50: =A50*E50 -> 4417 | E50: 0.1262
A51: 40000 | B51: =A51*C51 -> 9596 | C51: 0.2399 | D51: =A51*E51 -> 5820 | E51: 0.1455
...

Sheet Liquiditätsplanung, Anl. 7
M1: Anlage 7
A2: Liquiditätsplanung (Angaben in Euro, ohne Mwst.)
C4: 1. Jahr | G4: 2. Jahr | K4: 3. Jahr
A5: Zeitraum | B5: I. Q. | C5: II. Q. | D5: III. Q. | E5: IV. Q. | F5: I. Q. | G5: II. Q. | H5: III. Q. | I5: IV. Q. | J5: I. Q. | K5: II. Q. | L5: III. Q. | M5: IV. Q.
A6: Betriebsergebnis 1 (Anlage 4) | B6: =SUM('Aufw.- Ertr-pl., Anl. 4, monatl'!B24:D24) -> 22770 | C6: =SUM('Aufw.- Ertr-pl., Anl. 4, monatl'!E24:G24) -> 31270 | D6: =SUM('Aufw.- Ertr-pl., Anl. 4, monatl'!H24:J24) -> 36270 | E6: =SUM('Aufw.- Ertr-pl., Anl. 4, monatl'!K24:M24) -> 47280 | F6: ='Aufw.- Ertr-pl., Anl. 4, quart'!B24 -> 40770 | G6: ='Aufw.- Ertr-pl., Anl. 4, quart'!C24 -> 43770 | H6: ='Aufw.- Ertr-pl., Anl. 4, quart'!D24 -> 47770 | I6: ='Aufw.- Ertr-pl., Anl. 4, quart'!E24 -> 50770 | J6: ='Aufw.- Ertr-pl., Anl. 4, quart'!F24 -> 53770 | K6: ='Aufw.- Ertr-pl., Anl. 4, quart'!G24 -> 57770 | L6: ='Aufw.- Ertr-pl., Anl. 4, quart'!H24 -> 59770 | M6: ='Aufw.- Ertr-pl., Anl. 4, quart'!I24 -> 61770
A7: + Abschreibungen | B7: =SUM('Aufw.- Ertr-pl., Anl. 4, monatl'!B22:D22) -> 0 | C7: =SUM('Aufw.- Ertr-pl., Anl. 4, monatl'!E22:G22) -> 0 | D7: =SUM('Aufw.- Ertr-pl., Anl. 4, monatl'!H22:J22) -> 0 | E7: =SUM('Aufw.- Ertr-pl., Anl. 4, monatl'!K22:M22) -> 0 | F7: ='Aufw.- Ertr-pl., Anl. 4, quart'!B22 -> 0 | G7: ='Aufw.- Ertr-pl., Anl. 4, quart'!C22 -> 0 | H7: ='Aufw.- Ertr-pl., Anl. 4, quart'!D22 -> 0 | I7: ='Aufw.- Ertr-pl., Anl. 4, quart'!E22 -> 0 | J7: ='Aufw.- Ertr-pl., Anl. 4, quart'!F22 -> 0 | K7: ='Aufw.- Ertr-pl., Anl. 4, quart'!G22 -> 0 | L7: ='Aufw.- Ertr-pl., Anl. 4, quart'!H22 -> 0 | M7: ='Aufw.- Ertr-pl., Anl. 4, quart'!I22 -> 0
A8: + Einlagen (Eigenkapital etc.) | B8: 0
A9: + Zuschüsse (öffentl. Förderm.) | B9: ='Finanzbedarf netto, Anl. 5'!B42/3 -> 0
A10: + Kreditaufnahme | B10: =SUM('Finanzbedarf netto, Anl. 5'!B40) -> 0
A11: + Gründungszuschuss/Einstiegsgeld | B11: =SUM('Aufw.- Ertr-pl., Anl. 4, monatl'!B25:D25) -> 0 | C11: =SUM('Aufw.- Ertr-pl., Anl. 4, monatl'!E25:G25) -> 0 | D11: =SUM('Aufw.- Ertr-pl., Anl. 4, monatl'!H25:J25) -> 0 | E11: =SUM('Aufw.- Ertr-pl., Anl. 4, monatl'!K25:M25) -> 0 | F11: ='Aufw.- Ertr-pl., Anl. 4, quart'!B25 -> 0 | G11: ='Aufw.- Ertr-pl., Anl. 4, quart'!C25 -> 0 | H11: ='Aufw.- Ertr-pl., Anl. 4, quart'!D25 -> 0 | I11: ='Aufw.- Ertr-pl., Anl. 4, quart'!E25 -> 0
A12: ./.Investitionen (siehe Anl. 1) | B12: ='Investitionen, Anl. 1'!B59 -> 3500
A13: ./. Kautionen | B13: ='betr. Aufw, Anl.2, monatl.'!B32+B28 -> 300 | C13: ='betr. Aufw, Anl.2, monatl.'!C32+C28 -> 0 | D13: ='betr. Aufw, Anl.2, monatl.'!D32+D28 -> 0 | E13: ='betr. Aufw, Anl.2, monatl.'!E32+E28 -> 0 | F13: ='betr. Aufw, Anl.2, monatl.'!F32+F28 -> 0 | G13: ='betr. Aufw, Anl.2, monatl.'!G32+G28 -> 0 | H13: ='betr. Aufw, Anl.2, monatl.'!H32+H28 -> 0 | I13: ='betr. Aufw, Anl.2, monatl.'!I32+I28 -> 0 | ... M13: ='betr. Aufw, Anl.2, monatl.'!M32+M28 -> 0
A14: ./. Kredit-Tilgungen KfW (Raten) | B14: ='Rentabilitätsvorschau, Anl. 6'!B19/4 -> 0 | C14: ='Rentabilitätsvorschau, Anl. 6'!B19/4 -> 0 | D14: ='Rentabilitätsvorschau, Anl. 6'!B19/4 -> 0 | E14: ='Rentabilitätsvorschau, Anl. 6'!B19/4 -> 0 | F14: ='Rentabilitätsvorschau, Anl. 6'!C19/4 -> 0 | G14: ='Rentabilitätsvorschau, Anl. 6'!C19/4 -> 0 | H14: ='Rentabilitätsvorschau, Anl. 6'!C19/4 -> 0 | I14: ='Rentabilitätsvorschau, Anl. 6'!C19/4 -> 0 | J14: ='Rentabilitätsvorschau, Anl. 6'!D19/4 -> 0 | K14: ='Rentabilitätsvorschau, Anl. 6'!D19/4 -> 0 | L14: ='Rentabilitätsvorschau, Anl. 6'!D19/4 -> 0 | M14: ='Rentabilitätsvorschau, Anl. 6'!D19/4 -> 0
A15: ./. Zins-Zahlungen KfW | B15: ='Rentabilitätsvorschau, Anl. 6'!B20/4 -> 0 | C15: ='Rentabilitätsvorschau, Anl. 6'!B20/4 -> 0 | D15: ='Rentabilitätsvorschau, Anl. 6'!B20/4 -> 0 | E15: ='Rentabilitätsvorschau, Anl. 6'!B20/4 -> 0 | F15: ='Rentabilitätsvorschau, Anl. 6'!C20/4 -> 0 | G15: ='Rentabilitätsvorschau, Anl. 6'!C20/4 -> 0 | H15: ='Rentabilitätsvorschau, Anl. 6'!C20/4 -> 0 | I15: ='Rentabilitätsvorschau, Anl. 6'!C20/4 -> 0 | J15: ='Rentabilitätsvorschau, Anl. 6'!D20/4 -> 0 | K15: ='Rentabilitätsvorschau, Anl. 6'!D20/4 -> 0 | L15: ='Rentabilitätsvorschau, Anl. 6'!D20/4 -> 0 | M15: ='Rentabilitätsvorschau, Anl. 6'!D20/4 -> 0
A16: ./. Kredit-Tilgungen IBB (Raten) | B16: ='Rentabilitätsvorschau, Anl. 6'!B23/4 -> 0 | C16: ='Rentabilitätsvorschau, Anl. 6'!B23/4 -> 0 | D16: ='Rentabilitätsvorschau, Anl. 6'!B23/4 -> 0 | E16: ='Rentabilitätsvorschau, Anl. 6'!B23/4 -> 0 | F16: ='Rentabilitätsvorschau, Anl. 6'!C23/4 -> 0 | G16: ='Rentabilitätsvorschau, Anl. 6'!C23/4 -> 0 | H16: ='Rentabilitätsvorschau, Anl. 6'!C23/4 -> 0 | I16: ='Rentabilitätsvorschau, Anl. 6'!C23/4 -> 0 | J16: ='Rentabilitätsvorschau, Anl. 6'!D23/4 -> 0 | K16: ='Rentabilitätsvorschau, Anl. 6'!D23/4 -> 0 | L16: ='Rentabilitätsvorschau, Anl. 6'!D23/4 -> 0 | M16: ='Rentabilitätsvorschau, Anl. 6'!D23/4 -> 0
A17: ./. Kredit-Tilgungen (andere Kreditinstitute) | B17: ='Rentabilitätsvorschau, Anl. 6'!B25/4 -> 0 | C17: ='Rentabilitätsvorschau, Anl. 6'!B25/4 -> 0 | D17: ='Rentabilitätsvorschau, Anl. 6'!B25/4 -> 0 | E17: ='Rentabilitätsvorschau, Anl. 6'!B25/4 -> 0 | F17: ='Rentabilitätsvorschau, Anl. 6'!C25/4 -> 0 | G17: ='Rentabilitätsvorschau, Anl. 6'!C25/4 -> 0 | H17: ='Rentabilitätsvorschau, Anl. 6'!C25/4 -> 0 | I17: ='Rentabilitätsvorschau, Anl. 6'!C25/4 -> 0 | J17: ='Rentabilitätsvorschau, Anl. 6'!D25/4 -> 0 | K17: ='Rentabilitätsvorschau, Anl. 6'!D25/4 -> 0 | L17: ='Rentabilitätsvorschau, Anl. 6'!D25/4 -> 0 | M17: ='Rentabilitätsvorschau, Anl. 6'!D25/4 -> 0
A18: ./. Zins-Zahlungen (andere Kreditinstitute) | B18: ='Rentabilitätsvorschau, Anl. 6'!B25/4 -> 0 | C18: ='Rentabilitätsvorschau, Anl. 6'!B25/4 -> 0 | D18: ='Rentabilitätsvorschau, Anl. 6'!B25/4 -> 0 | E18: ='Rentabilitätsvorschau, Anl. 6'!E26/4 -> 0 | F18: ='Rentabilitätsvorschau, Anl. 6'!C25/4 -> 0 | G18: ='Rentabilitätsvorschau, Anl. 6'!C25/4 -> 0 | H18: ='Rentabilitätsvorschau, Anl. 6'!C25/4 -> 0 | I18: ='Rentabilitätsvorschau, Anl. 6'!C25/4 -> 0 | J18: ='Rentabilitätsvorschau, Anl. 6'!D25/4 -> 0 | K18: ='Rentabilitätsvorschau, Anl. 6'!D25/4 -> 0 | L18: ='Rentabilitätsvorschau, Anl. 6'!D25/4 -> 0 | M18: ='Rentabilitätsvorschau, Anl. 6'!D25/4 -> 0
A19: ./. Kreditbearbeitungsgebühren (gesamt) | B19: ='Rentabilitätsvorschau, Anl. 6'!B18+'Rentabilitätsvorschau, Anl. 6'!B21+'Rentabilitätsvorschau, Anl. 6'!B24 -> 0
A20: ./. Kontokorrentkosten
A21: ./. Entnahmen (Unternehmerlohn etc.) | B21: =SUM('Aufw.- Ertr-pl., Anl. 4, monatl'!B26:D26) -> 8295 | C21: =SUM('Aufw.- Ertr-pl., Anl. 4, monatl'!E26:G26) -> 8295 | D21: =SUM('Aufw.- Ertr-pl., Anl. 4, monatl'!H26:J26) -> 8295 | E21: =SUM('Aufw.- Ertr-pl., Anl. 4, monatl'!K26:M26) -> 8295 | F21: ='Aufw.- Ertr-pl., Anl. 4, quart'!B26 -> 8295 | G21: ='Aufw.- Ertr-pl., Anl. 4, quart'!C26 -> 8295 | H21: ='Aufw.- Ertr-pl., Anl. 4, quart'!D26 -> 8295 | I21: ='Aufw.- Ertr-pl., Anl. 4, quart'!E26 -> 8295 | J21: ='Aufw.- Ertr-pl., Anl. 4, quart'!F26 -> 8295 | K21: ='Aufw.- Ertr-pl., Anl. 4, quart'!G26 -> 8295 | L21: ='Aufw.- Ertr-pl., Anl. 4, quart'!H26 -> 8295 | M21: ='Aufw.- Ertr-pl., Anl. 4, quart'!I26 -> 8295
A22: ./. Mehrwertsteuerzahllast | B22: ='Ermittlung der MwSt., Anl. 8'!B32 -> 5130 | C22: ='Ermittlung der MwSt., Anl. 8'!C32 -> 5941.3 | D22: ='Ermittlung der MwSt., Anl. 8'!D32 -> 7159.2 | E22: ='Ermittlung der MwSt., Anl. 8'!E32 -> 8983.2 | F22: ='Ermittlung der MwSt., Anl. 8'!F32 -> 7746.3 | G22: ='Ermittlung der MwSt., Anl. 8'!G32 -> 8316.3 | H22: ='Ermittlung der MwSt., Anl. 8'!H32 -> 9076.3 | I22: ='Ermittlung der MwSt., Anl. 8'!I32 -> 9646.3 | ... M22: ='Ermittlung der MwSt., Anl. 8'!M32 -> 11736.3
A25: Liquidität | B25: 0 | C25: =C6+SUM(C7:C11)-SUM(C12:C21)+C22 -> 28916.3 | D25: =D6+SUM(D7:D11)-SUM(D12:D21)+D22 -> 35134.2 | E25: =E6+SUM(E7:E11)-SUM(E12:E21)+E22 -> 47968.2 | F25: =F6+SUM(F7:F11)-SUM(F12:F21)+F22 -> 40221.3 | G25: =G6+SUM(G7:G11)-SUM(G12:G21)+G22 -> 43791.3 | H25: =H6+SUM(H7:H11)-SUM(H12:H21)+H22 -> 48551.3 | I25: =I6+SUM(I7:I11)-SUM(I12:I21)+I22 -> 52121.3 | J25: =J6+SUM(J7:J11)-SUM(J12:J21)+J22 -> 55691.3 | ... M25: =M6+SUM(M7:M11)-SUM(M12:M21)+M22 -> 65211.3
A26: Liquidität kumulativ | C26: =B25+C25 -> 28916.3 | D26: =C26+D25 -> 64050.5 | E26: =D26+E25 -> 112018.7 | F26: =E26+F25 -> 152240 | G26: =F26+G25 -> 196031.3 | H26: =G26+H25 -> 244582.6 | I26: =H26+I25 -> 296703.9 | J26: =I26+J25 -> 352395.2 | K26: =J26+K25 -> 412846.5 | ... M26: =L26+M25 -> 540889.1

Sheet Ermittlung der MwSt., Anl. 8
M1: Anlage 8
A2: Ermittlung der Mehrwertsteuer (Angaben in Euro)
B4: 1. Jahr | F4: 2. Jahr | J4: 3. Jahr
A5: Zeitraum | B5: I. Q. | C5: II. Q. | D5: III. Q. | E5: IV. Q. | F5: I. Q. | G5: II. Q. | H5: III. Q. | I5: IV. Q. | J5: I. Q. | K5: II. Q. | L5: III. Q. | M5: IV. Q.
A6: Umsatzerlöse (netto) | B6: =SUM('Aufw.- Ertr-pl., Anl. 4, monatl'!B18:D18) -> 27000 | C6: =SUM('Aufw.- Ertr-pl., Anl. 4, monatl'!E18:G18) -> 35500 | D6: =SUM('Aufw.- Ertr-pl., Anl. 4, monatl'!H18:J18) -> 40500 | E6: =SUM('Aufw.- Ertr-pl., Anl. 4, monatl'!K18:M18) -> 51510 | F6: ='Aufw.- Ertr-pl., Anl. 4, quart'!B18 -> 45000 | G6: ='Aufw.- Ertr-pl., Anl. 4, quart'!C18 -> 48000 | H6: ='Aufw.- Ertr-pl., Anl. 4, quart'!D18 -> 52000 | I6: ='Aufw.- Ertr-pl., Anl. 4, quart'!E18 -> 55000 | J6: ='Aufw.- Ertr-pl., Anl. 4, quart'!F18 -> 58000 | K6: ='Aufw.- Ertr-pl., Anl. 4, quart'!G18 -> 62000 | L6: ='Aufw.- Ertr-pl., Anl. 4, quart'!H18 -> 64000 | M6: ='Aufw.- Ertr-pl., Anl. 4, quart'!I18 -> 66000
A7: Mehrwertsteuer | B7: =B6*19% -> 5130 | C7: =C6*19% -> 6745 | D7: =D6*19% -> 7695 | E7: =E6*19% -> 9786.9 | F7: =F6*19% -> 8550 | G7: =G6*19% -> 9120 | H7: =H6*19% -> 9880 | I7: =I6*19% -> 10450 | ... M7: =M6*19% -> 12540
A8: Umsatzerlöse (brutto) | B8: =B6+B7 -> 32130 | C8: =C6+C7 -> 42245 | D8: =D6+D7 -> 48195 | E8: =E6+E7 -> 61296.9 | F8: =F6+F7 -> 53550 | G8: =G6+G7 -> 57120 | H8: =H6+H7 -> 61880 | I8: =I6+I7 -> 65450 | ... M8: =M6+M7 -> 78540
A10: sonstige betriebl. Einnahmen (netto) | B10: =SUM('Aufw.- Ertr-pl., Anl. 4, monatl'!B23:D23) -> 0 | C10: =SUM('Aufw.- Ertr-pl., Anl. 4, monatl'!E23:F23) -> 0 | D10: =SUM('Aufw.- Ertr-pl., Anl. 4, monatl'!H23:J23) -> 0 | E10: =SUM('Aufw.- Ertr-pl., Anl. 4, monatl'!K23:M23) -> 0 | F10: ='Aufw.- Ertr-pl., Anl. 4, quart'!B23 -> 0 | G10: ='Aufw.- Ertr-pl., Anl. 4, quart'!C23 -> 0 | H10: ='Aufw.- Ertr-pl., Anl. 4, quart'!D23 -> 0 | I10: ='Aufw.- Ertr-pl., Anl. 4, quart'!E23 -> 0 | J10: ='Aufw.- Ertr-pl., Anl. 4, quart'!F23 -> 0 | K10: ='Aufw.- Ertr-pl., Anl. 4, quart'!G23 -> 0 | L10: ='Aufw.- Ertr-pl., Anl. 4, quart'!H23 -> 0 | M10: ='Aufw.- Ertr-pl., Anl. 4, quart'!I23 -> 0
A11: Mehrwertsteuer | B11: =B10*19% -> 0 | C11: =C10*19% -> 0 | D11: =D10*19% -> 0 | E11: =E10*19% -> 0 | F11: =F10*19% -> 0 | G11: =G10*19% -> 0 | H11: =H10*19% -> 0 | I11: =I10*19% -> 0 | ... M11: =M10*19% -> 0
A12: sonstige betrieblichen Einnahmen (brutto) | B12: =B10+B11 -> 0 | C12: =C10+C11 -> 0 | D12: =D10+D11 -> 0 | E12: =E10+E11 -> 0 | F12: =F10+F11 -> 0 | G12: =G10+G11 -> 0 | H12: =H10+H11 -> 0 | I12: =I10+I11 -> 0 | ... M12: =M10+M11 -> 0
A14: Materialaufwand (netto) | C14: ='Aufw.- Ertr-pl., Anl. 4, monatl'!C10+'Aufw.- Ertr-pl., Anl. 4, monatl'!C13+'Aufw.- Ertr-pl., Anl. 4, monatl'!C16 -> 0 | D14: ='Aufw.- Ertr-pl., Anl. 4, monatl'!D10+'Aufw.- Ertr-pl., Anl. 4, monatl'!D13+'Aufw.- Ertr-pl., Anl. 4, monatl'!D16 -> 0 | E14: ='Aufw.- Ertr-pl., Anl. 4, monatl'!E10+'Aufw.- Ertr-pl., Anl. 4, monatl'!E13+'Aufw.- Ertr-pl., Anl. 4, monatl'!E16 -> 0 | F14: ='Aufw.- Ertr-pl., Anl. 4, quart'!B10+'Aufw.- Ertr-pl., Anl. 4, quart'!B13+'Aufw.- Ertr-pl., Anl. 4, quart'!B16 -> 0 | G14: ='Aufw.- Ertr-pl., Anl. 4, quart'!C10+'Aufw.- Ertr-pl., Anl. 4, quart'!C13+'Aufw.- Ertr-pl., Anl. 4, quart'!C16 -> 0 | H14: ='Aufw.- Ertr-pl., Anl. 4, quart'!D10+'Aufw.- Ertr-pl., Anl. 4, quart'!D13+'Aufw.- Ertr-pl., Anl. 4, quart'!D16 -> 0 | I14: ='Aufw.- Ertr-pl., Anl. 4, quart'!E10+'Aufw.- Ertr-pl., Anl. 4, quart'!E13+'Aufw.- Ertr-pl., Anl. 4, quart'!E16 -> 0 | J14: ='Aufw.- Ertr-pl., Anl. 4, quart'!F10+'Aufw.- Ertr-pl., Anl. 4, quart'!F13+'Aufw.- Ertr-pl., Anl. 4, quart'!F16 -> 0 | K14: ='Aufw.- Ertr-pl., Anl. 4, quart'!G10+'Aufw.- Ertr-pl., Anl. 4, quart'!G13+'Aufw.- Ertr-pl., Anl. 4, quart'!G16 -> 0 | L14: ='Aufw.- Ertr-pl., Anl. 4, quart'!H10+'Aufw.- Ertr-pl., Anl. 4, quart'!H13+'Aufw.- Ertr-pl., Anl. 4, quart'!H16 -> 0 | M14: ='Aufw.- Ertr-pl., Anl. 4, quart'!I10+'Aufw.- Ertr-pl., Anl. 4, quart'!I13+'Aufw.- Ertr-pl., Anl. 4, quart'!I16 -> 0
A15: Vorsteuer | B15: =B14*19% -> 0 | C15: =C14*19% -> 0 | D15: =D14*19% -> 0 | E15: =E14*19% -> 0 | F15: =F14*19% -> 0 | G15: =G14*19% -> 0 | H15: =H14*19% -> 0 | I15: =I14*19% -> 0 | ... M15: =M14*19% -> 0
A16: Materialaufwand (brutto) | B16: =B14+B15 -> 0 | C16: =C14+C15 -> 0 | D16: =D14+D15 -> 0 | E16: =E14+E15 -> 0 | F16: =F14+F15 -> 0 | G16: =G14+G15 -> 0 | H16: =H14+H15 -> 0 | I16: =I14+I15 -> 0 | ... M16: =M14+M15 -> 0
A18: Fremdleistungen (netto) | C18: ='Aufw.- Ertr-pl., Anl. 4, monatl'!C11+'Aufw.- Ertr-pl., Anl. 4, monatl'!C14+'Aufw.- Ertr-pl., Anl. 4, monatl'!C17 -> 0 | D18: ='Aufw.- Ertr-pl., Anl. 4, monatl'!D11+'Aufw.- Ertr-pl., Anl. 4, monatl'!D14+'Aufw.- Ertr-pl., Anl. 4, monatl'!D17 -> 0 | E18: ='Aufw.- Ertr-pl., Anl. 4, monatl'!E11+'Aufw.- Ertr-pl., Anl. 4, monatl'!E14+'Aufw.- Ertr-pl., Anl. 4, monatl'!E17 -> 0 | F18: ='Aufw.- Ertr-pl., Anl. 4, quart'!B11+'Aufw.- Ertr-pl., Anl. 4, quart'!B14+'Aufw.- Ertr-pl., Anl. 4, quart'!B17 -> 0 | G18: ='Aufw.- Ertr-pl., Anl. 4, quart'!C11+'Aufw.- Ertr-pl., Anl. 4, quart'!C14+'Aufw.- Ertr-pl., Anl. 4, quart'!C17 -> 0 | H18: ='Aufw.- Ertr-pl., Anl. 4, quart'!D11+'Aufw.- Ertr-pl., Anl. 4, quart'!D14+'Aufw.- Ertr-pl., Anl. 4, quart'!D17 -> 0 | I18: ='Aufw.- Ertr-pl., Anl. 4, quart'!E11+'Aufw.- Ertr-pl., Anl. 4, quart'!E14+'Aufw.- Ertr-pl., Anl. 4, quart'!E17 -> 0 | J18: ='Aufw.- Ertr-pl., Anl. 4, quart'!F11+'Aufw.- Ertr-pl., Anl. 4, quart'!F14+'Aufw.- Ertr-pl., Anl. 4, quart'!F17 -> 0 | K18: ='Aufw.- Ertr-pl., Anl. 4, quart'!G11+'Aufw.- Ertr-pl., Anl. 4, quart'!G14+'Aufw.- Ertr-pl., Anl. 4, quart'!G17 -> 0 | L18: ='Aufw.- Ertr-pl., Anl. 4, quart'!H11+'Aufw.- Ertr-pl., Anl. 4, quart'!H14+'Aufw.- Ertr-pl., Anl. 4, quart'!H17 -> 0 | M18: ='Aufw.- Ertr-pl., Anl. 4, quart'!I11+'Aufw.- Ertr-pl., Anl. 4, quart'!I14+'Aufw.- Ertr-pl., Anl. 4, quart'!I17 -> 0
A19: Vorsteuer | B19: =B18*19% -> 0 | C19: =C18*19% -> 0 | D19: =D18*19% -> 0 | E19: =E18*19% -> 0 | F19: =F18*19% -> 0 | G19: =G18*19% -> 0 | H19: =H18*19% -> 0 | I19: =I18*19% -> 0 | ... M19: =M18*19% -> 0
A20: Fremdleistungen (brutto) | B20: =B18+B19 -> 0 | C20: =C18+C19 -> 0 | D20: =D18+D19 -> 0 | E20: =E18+E19 -> 0 | F20: =F18+F19 -> 0 | G20: =G18+G19 -> 0 | H20: =H18+H19 -> 0 | I20: =I18+I19 -> 0 | ... M20: =M18+M19 -> 0
A22: sonstiger betriebl. Aufwand (netto) | C22: =SUM('betr. Aufw, Anl.2, monatl.'!E28:G28) -> 4230 | D22: =SUM('betr. Aufw, Anl.2, monatl.'!H28:I28) -> 2820 | E22: =SUM('betr. Aufw, Anl.2, monatl.'!K28:M28) -> 4230 | F22: ='betr. Aufw, Anl.2,quart'!B25 -> 4230 | G22: ='betr. Aufw, Anl.2,quart'!C25 -> 4230 | H22: ='betr. Aufw, Anl.2,quart'!D25 -> 4230 | I22: ='betr. Aufw, Anl.2,quart'!E25 -> 4230 | J22: ='betr. Aufw, Anl.2,quart'!F25 -> 4230 | K22: ='betr. Aufw, Anl.2,quart'!G25 -> 4230 | L22: ='betr. Aufw, Anl.2,quart'!H25 -> 4230 | M22: ='betr. Aufw, Anl.2,quart'!I25 -> 4230
A23: Vorsteuer | B23: =B22*19% -> 0 | C23: =C22*19% -> 803.7 | D23: =D22*19% -> 535.8 | E23: =E22*19% -> 803.7 | F23: =F22*19% -> 803.7 | G23: =G22*19% -> 803.7 | H23: =H22*19% -> 803.7 | I23: =I22*19% -> 803.7 | ... M23: =M22*19% -> 803.7
A24: sonstiger betrieblicher Aufwand (brutto) | B24: =B22+B23 -> 0 | C24: =C22+C23 -> 5033.7 | D24: =D22+D23 -> 3355.8 | E24: =E22+E23 -> 5033.7 | F24: =F22+F23 -> 5033.7 | G24: =G22+G23 -> 5033.7 | H24: =H22+H23 -> 5033.7 | I24: =I22+I23 -> 5033.7 | ... M24: =M22+M23 -> 5033.7
A26: Summe der Investitionen (netto) | C26: ='Liquiditätsplanung, Anl. 7'!C12 | D26: ='Liquiditätsplanung, Anl. 7'!D12 | E26: ='Liquiditätsplanung, Anl. 7'!E12 | F26: ='Liquiditätsplanung, Anl. 7'!F12 | G26: ='Liquiditätsplanung, Anl. 7'!G12 | H26: ='Liquiditätsplanung, Anl. 7'!H12 | I26: ='Liquiditätsplanung, Anl. 7'!I12 | J26: ='Liquiditätsplanung, Anl. 7'!J12 | ... M26: ='Liquiditätsplanung, Anl. 7'!M12
A27: Vorsteuer | B27: =B26*19% -> 0 | C27: =C26*19% -> 0 | D27: =D26*19% -> 0 | E27: =E26*19% -> 0 | F27: =F26*19% -> 0 | G27: =G26*19% -> 0 | H27: =H26*19% -> 0 | I27: =I26*19% -> 0 | ... M27: =M26*19% -> 0
A28: Summe der Investitionen (brutto) | B28: =B26+B27 -> 0 | C28: =C26+C27 -> 0 | D28: =D26+D27 -> 0 | E28: =E26+E27 -> 0 | F28: =F26+F27 -> 0 | G28: =G26+G27 -> 0 | H28: =H26+H27 -> 0 | I28: =I26+I27 -> 0 | ... M28: =M26+M27 -> 0
A30: Mehrwertsteuer gesamt | B30: =B7+B11 -> 5130 | C30: =SUM(C7,C11) -> 6745 | D30: =SUM(D7,D11) -> 7695 | E30: =SUM(E7,E11) -> 9786.9 | F30: =SUM(F7,F11) -> 8550 | G30: =SUM(G7,G11) -> 9120 | H30: =SUM(H7,H11) -> 9880 | I30: =SUM(I7,I11) -> 10450 | J30: =SUM(J7,J11) -> 11020 | ... M30: =SUM(M7,M11) -> 12540
A31: ./.Vorsteuer gesamt | B31: =B15+B19+B23+B27 -> 0 | C31: =SUM(C15,C19,C23,C27) -> 803.7 | D31: =SUM(D15,D19,D23,D27) -> 535.8 | E31: =SUM(E15,E19,E23,E27) -> 803.7 | F31: =SUM(F15,F19,F23,F27) -> 803.7 | G31: =SUM(G15,G19,G23,G27) -> 803.7 | H31: =SUM(H15,H19,H23,H27) -> 803.7 | I31: =SUM(I15,I19,I23,I27) -> 803.7 | J31: =SUM(J15,J19,J23,J27) -> 803.7 | ... M31: =SUM(M15,M19,M23,M27) -> 803.7
A32: Mehrwertsteuerzahllast | B32: =B30-B31 -> 5130 | C32: =C30-C31 -> 5941.3 | D32: =D30-D31 -> 7159.2 | E32: =E30-E31 -> 8983.2 | F32: =F30-F31 -> 7746.3 | G32: =G30-G31 -> 8316.3 | H32: =H30-H31 -> 9076.3 | I32: =I30-I31 -> 9646.3 | ... M32: =M30-M31 -> 11736.3
